{
 "cells": [
  {
   "cell_type": "code",
   "execution_count": 1,
   "metadata": {},
   "outputs": [],
   "source": [
    "\n",
    "import pandas as pd\n",
    "import numpy as np"
   ]
  },
  {
   "cell_type": "code",
   "execution_count": 2,
   "metadata": {},
   "outputs": [],
   "source": [
    "randomseed = 7\n",
    "np.random.seed(randomseed)"
   ]
  },
  {
   "cell_type": "code",
   "execution_count": 3,
   "metadata": {},
   "outputs": [
    {
     "name": "stderr",
     "output_type": "stream",
     "text": [
      "C:\\ProgramData\\Anaconda3\\lib\\site-packages\\IPython\\core\\interactiveshell.py:3072: DtypeWarning: Columns (8,13,15,16,17,41) have mixed types.Specify dtype option on import or set low_memory=False.\n",
      "  interactivity=interactivity, compiler=compiler, result=result)\n"
     ]
    },
    {
     "name": "stdout",
     "output_type": "stream",
     "text": [
      "(185843, 19)\n"
     ]
    },
    {
     "name": "stderr",
     "output_type": "stream",
     "text": [
      "C:\\ProgramData\\Anaconda3\\lib\\site-packages\\IPython\\core\\interactiveshell.py:3072: DtypeWarning: Columns (13,16,17,40,88,89,94,104,105) have mixed types.Specify dtype option on import or set low_memory=False.\n",
      "  interactivity=interactivity, compiler=compiler, result=result)\n"
     ]
    },
    {
     "name": "stdout",
     "output_type": "stream",
     "text": [
      "(185843, 2)\n",
      "(169024, 20)\n",
      "(56542, 13)\n",
      "1045 17331 38166\n"
     ]
    }
   ],
   "source": [
    "# read the data set\n",
    "x_original = pd.read_csv(\"../../../../dataset/XLable_onlyDiabeticRemoved.txt\")\n",
    "\n",
    "conditions = [\n",
    "    (x_original.L100800 < 100),\n",
    "    (x_original.L100800 >= 100) & (x_original.L100800 < 126),\n",
    "    (x_original.L100800 >= 126),\n",
    "]\n",
    "choices = [0, 1, 2]\n",
    "x_original[\"CLASS\"] = np.select(conditions, choices, default=0)\n",
    "x_original = x_original[\n",
    "    [\n",
    "        \"Unnamed: 0\",\n",
    "        \"L100800\",\n",
    "        \"L104600\",\n",
    "        \"L103000\",\n",
    "        \"S000300\",\n",
    "        \"L101700\",\n",
    "        \"L100700\",\n",
    "        \"FIELD_33\",\n",
    "        \"FIELD_38\",\n",
    "        \"FIELD_40\",\n",
    "        \"FIELD_31\",\n",
    "        \"SEX\",\n",
    "        \"AGE\",  #'CLASS',\n",
    "        \"FIELD_16\",\n",
    "        \"FIELD_23\",\n",
    "        \"FIELD_15\",\n",
    "        \"FIELD_22\",\n",
    "        \"FIELD_17\",\n",
    "        \"FIELD_24\",\n",
    "    ]\n",
    "]\n",
    "\n",
    "print(x_original.shape)\n",
    "\n",
    "y_original = pd.read_csv(\"../../../../dataset/TargetLable_onlyDiabeticRemoved.txt\")\n",
    "\n",
    "conditions = [\n",
    "    (y_original.L100800 < 100),\n",
    "    (y_original.L100800 >= 100) & (y_original.L100800 < 126),\n",
    "    (y_original.L100800 >= 126),\n",
    "]\n",
    "\n",
    "choices = [0, 1, 2]\n",
    "y_original[\"CLASS\"] = np.select(conditions, choices, default=0)\n",
    "\n",
    "y_original = y_original[[\"Unnamed: 0\", \"CLASS\"]]\n",
    "\n",
    "print(y_original.shape)\n",
    "\n",
    "data = pd.merge(\n",
    "    x_original, y_original, how=\"inner\", left_on=\"Unnamed: 0\", right_on=\"Unnamed: 0\"\n",
    ")\n",
    "\n",
    "# filter the data set\n",
    "data = data[data.FIELD_16 != 1]  # exclude people who are diagnosed for (diabetes)\n",
    "data = data[data.FIELD_23 != 1]  # exclude people who are on medication for diabetes\n",
    "\n",
    "data = data[\n",
    "    data.FIELD_15 != 1\n",
    "]  # exclude people who are diagnosed for (high blood pressure)\n",
    "data = data[\n",
    "    data.FIELD_22 != 1\n",
    "]  # exclude people who are on medication for high blood pressure\n",
    "\n",
    "data = data[data.FIELD_17 != 1]  # exclude people who are diagnosed for hyperlipidemia\n",
    "data = data[\n",
    "    data.FIELD_24 != 1\n",
    "]  # exclude people who are on medication for hyperlipidemia\n",
    "\n",
    "print(data.shape)\n",
    "\n",
    "data = data[\n",
    "    [\n",
    "        \"L100800\",\n",
    "        \"L104600\",\n",
    "        \"L103000\",\n",
    "        \"S000300\",\n",
    "        \"L101700\",\n",
    "        \"L100700\",\n",
    "        \"FIELD_33\",\n",
    "        \"FIELD_38\",\n",
    "        \"FIELD_40\",\n",
    "        \"FIELD_31\",\n",
    "        \"SEX\",\n",
    "        \"AGE\",\n",
    "        \"CLASS\",\n",
    "    ]\n",
    "]\n",
    "data = data.dropna()\n",
    "print(data.shape)\n",
    "data.head()\n",
    "\n",
    "diabetic = data[data.CLASS == 2]\n",
    "prediabetic = data[data.CLASS == 1]\n",
    "normal = data[data.CLASS == 0]\n",
    "\n",
    "print(diabetic.shape[0], prediabetic.shape[0], normal.shape[0])\n",
    "\n",
    "diabetic_test = diabetic.sample(200, random_state=randomseed)\n",
    "prediabetic_test = prediabetic.sample(200, random_state=randomseed)\n",
    "normal_test = normal.sample(200, random_state=randomseed)\n",
    "test = pd.concat([diabetic_test, prediabetic_test, normal_test])\n",
    "\n",
    "diabetic_train = diabetic.drop(diabetic_test.index)\n",
    "prediabetic_train = prediabetic.drop(prediabetic_test.index)\n",
    "# .sample(\n",
    "#     10 * diabetic_train.shape[0], random_state=randomseed\n",
    "# )\n",
    "normal_train = normal.drop(normal_test.index).sample(\n",
    "    prediabetic_train.shape[0],\n",
    "    random_state=randomseed\n",
    "    #     10 * diabetic_train.shape[0], random_state=randomseed\n",
    ")\n",
    "train = pd.concat([diabetic_train, diabetic_train, prediabetic_train, normal_train])\n",
    " \n",
    "\n",
    "xtrain = train.iloc[:, :-1]\n",
    "xtest = test.iloc[:, :-1]\n",
    "\n",
    "ytest = test.iloc[:, -1]\n",
    "ytrain = train.iloc[:, -1]\n",
    "\n"
   ]
  },
  {
   "cell_type": "code",
   "execution_count": 4,
   "metadata": {},
   "outputs": [
    {
     "name": "stderr",
     "output_type": "stream",
     "text": [
      "Using TensorFlow backend.\n"
     ]
    }
   ],
   "source": [
    "from keras.models import Sequential\n",
    "from keras.layers import Dense\n",
    "import matplotlib.pyplot as plt\n",
    "import pandas as pd\n",
    "from sklearn import preprocessing\n",
    "from sklearn.preprocessing import MinMaxScaler\n",
    "\n"
   ]
  },
  {
   "cell_type": "code",
   "execution_count": 5,
   "metadata": {},
   "outputs": [
    {
     "name": "stdout",
     "output_type": "stream",
     "text": [
      "(35952, 12)\n",
      "(35952,)\n"
     ]
    }
   ],
   "source": [
    "print(xtrain.shape)\n",
    "print(ytrain.shape)\n"
   ]
  },
  {
   "cell_type": "code",
   "execution_count": null,
   "metadata": {
    "scrolled": false
   },
   "outputs": [
    {
     "name": "stderr",
     "output_type": "stream",
     "text": [
      "C:\\ProgramData\\Anaconda3\\lib\\site-packages\\ipykernel_launcher.py:3: UserWarning: Update your `Dense` call to the Keras 2 API: `Dense(12, input_dim=12, activation=\"relu\", kernel_initializer=\"uniform\")`\n",
      "  This is separate from the ipykernel package so we can avoid doing imports until\n",
      "C:\\ProgramData\\Anaconda3\\lib\\site-packages\\ipykernel_launcher.py:4: UserWarning: Update your `Dense` call to the Keras 2 API: `Dense(10, activation=\"relu\", kernel_initializer=\"uniform\")`\n",
      "  after removing the cwd from sys.path.\n",
      "C:\\ProgramData\\Anaconda3\\lib\\site-packages\\ipykernel_launcher.py:5: UserWarning: Update your `Dense` call to the Keras 2 API: `Dense(1, activation=\"relu\", kernel_initializer=\"uniform\")`\n",
      "  \"\"\"\n",
      "C:\\ProgramData\\Anaconda3\\lib\\site-packages\\ipykernel_launcher.py:8: UserWarning: The `nb_epoch` argument in `fit` has been renamed `epochs`.\n",
      "  \n"
     ]
    },
    {
     "name": "stdout",
     "output_type": "stream",
     "text": [
      "Epoch 1/100\n"
     ]
    },
    {
     "name": "stderr",
     "output_type": "stream",
     "text": [
      "ERROR:root:Internal Python error in the inspect module.\n",
      "Below is the traceback from this internal error.\n",
      "\n",
      "ERROR:root:Internal Python error in the inspect module.\n",
      "Below is the traceback from this internal error.\n",
      "\n",
      "ERROR:root:Internal Python error in the inspect module.\n",
      "Below is the traceback from this internal error.\n",
      "\n"
     ]
    },
    {
     "name": "stdout",
     "output_type": "stream",
     "text": [
      "Traceback (most recent call last):\n",
      "  File \"C:\\ProgramData\\Anaconda3\\lib\\site-packages\\IPython\\core\\interactiveshell.py\", line 3343, in run_code\n",
      "    exec(code_obj, self.user_global_ns, self.user_ns)\n",
      "  File \"<ipython-input-6-0d21aaf95e20>\", line 8, in <module>\n",
      "    history = model.fit(np.array(xtrain), np.array(ytrain), nb_epoch=100, batch_size=50,  verbose=1)\n",
      "  File \"C:\\ProgramData\\Anaconda3\\lib\\site-packages\\keras\\engine\\training.py\", line 1239, in fit\n",
      "    validation_freq=validation_freq)\n",
      "  File \"C:\\ProgramData\\Anaconda3\\lib\\site-packages\\keras\\engine\\training_arrays.py\", line 196, in fit_loop\n",
      "    outs = fit_function(ins_batch)\n",
      "  File \"C:\\ProgramData\\Anaconda3\\lib\\site-packages\\tensorflow_core\\python\\keras\\backend.py\", line 3727, in __call__\n",
      "    outputs = self._graph_fn(*converted_inputs)\n",
      "  File \"C:\\ProgramData\\Anaconda3\\lib\\site-packages\\tensorflow_core\\python\\eager\\function.py\", line 1551, in __call__\n",
      "    return self._call_impl(args, kwargs)\n",
      "  File \"C:\\ProgramData\\Anaconda3\\lib\\site-packages\\tensorflow_core\\python\\eager\\function.py\", line 1591, in _call_impl\n",
      "    return self._call_flat(args, self.captured_inputs, cancellation_manager)\n",
      "  File \"C:\\ProgramData\\Anaconda3\\lib\\site-packages\\tensorflow_core\\python\\eager\\function.py\", line 1692, in _call_flat\n",
      "    ctx, args, cancellation_manager=cancellation_manager))\n",
      "  File \"C:\\ProgramData\\Anaconda3\\lib\\site-packages\\tensorflow_core\\python\\eager\\function.py\", line 545, in call\n",
      "    ctx=ctx)\n",
      "  File \"C:\\ProgramData\\Anaconda3\\lib\\site-packages\\tensorflow_core\\python\\eager\\execute.py\", line 67, in quick_execute\n",
      "    six.raise_from(core._status_to_exception(e.code, message), None)\n",
      "  File \"<string>\", line 3, in raise_from\n",
      "tensorflow.python.framework.errors_impl.InternalError:  Blas GEMM launch failed : a.shape=(50, 12), b.shape=(12, 12), m=50, n=12, k=12\n",
      "\t [[node dense_1/MatMul (defined at C:\\ProgramData\\Anaconda3\\lib\\site-packages\\keras\\backend\\tensorflow_backend.py:3009) ]] [Op:__inference_keras_scratch_graph_1062]\n",
      "\n",
      "Function call stack:\n",
      "keras_scratch_graph\n",
      "\n",
      "\n",
      "During handling of the above exception, another exception occurred:\n",
      "\n",
      "Traceback (most recent call last):\n",
      "  File \"C:\\ProgramData\\Anaconda3\\lib\\site-packages\\IPython\\core\\interactiveshell.py\", line 2044, in showtraceback\n",
      "    stb = value._render_traceback_()\n",
      "AttributeError: 'InternalError' object has no attribute '_render_traceback_'\n",
      "\n",
      "During handling of the above exception, another exception occurred:\n",
      "\n",
      "Traceback (most recent call last):\n",
      "  File \"C:\\ProgramData\\Anaconda3\\lib\\site-packages\\IPython\\core\\ultratb.py\", line 1169, in get_records\n",
      "    return _fixed_getinnerframes(etb, number_of_lines_of_context, tb_offset)\n",
      "  File \"C:\\ProgramData\\Anaconda3\\lib\\site-packages\\IPython\\core\\ultratb.py\", line 316, in wrapped\n",
      "    return f(*args, **kwargs)\n",
      "  File \"C:\\ProgramData\\Anaconda3\\lib\\site-packages\\IPython\\core\\ultratb.py\", line 350, in _fixed_getinnerframes\n",
      "    records = fix_frame_records_filenames(inspect.getinnerframes(etb, context))\n",
      "  File \"C:\\ProgramData\\Anaconda3\\lib\\inspect.py\", line 1502, in getinnerframes\n",
      "    frameinfo = (tb.tb_frame,) + getframeinfo(tb, context)\n",
      "  File \"C:\\ProgramData\\Anaconda3\\lib\\inspect.py\", line 1460, in getframeinfo\n",
      "    filename = getsourcefile(frame) or getfile(frame)\n",
      "  File \"C:\\ProgramData\\Anaconda3\\lib\\inspect.py\", line 696, in getsourcefile\n",
      "    if getattr(getmodule(object, filename), '__loader__', None) is not None:\n",
      "  File \"C:\\ProgramData\\Anaconda3\\lib\\inspect.py\", line 733, in getmodule\n",
      "    if ismodule(module) and hasattr(module, '__file__'):\n",
      "  File \"C:\\ProgramData\\Anaconda3\\lib\\site-packages\\tensorflow\\__init__.py\", line 50, in __getattr__\n",
      "    module = self._load()\n",
      "  File \"C:\\ProgramData\\Anaconda3\\lib\\site-packages\\tensorflow\\__init__.py\", line 44, in _load\n",
      "    module = _importlib.import_module(self.__name__)\n",
      "  File \"C:\\ProgramData\\Anaconda3\\lib\\importlib\\__init__.py\", line 127, in import_module\n",
      "    return _bootstrap._gcd_import(name[level:], package, level)\n",
      "  File \"<frozen importlib._bootstrap>\", line 1006, in _gcd_import\n",
      "  File \"<frozen importlib._bootstrap>\", line 983, in _find_and_load\n",
      "  File \"<frozen importlib._bootstrap>\", line 965, in _find_and_load_unlocked\n",
      "ModuleNotFoundError: No module named 'tensorflow_core.estimator'\n",
      "Traceback (most recent call last):\n",
      "  File \"C:\\ProgramData\\Anaconda3\\lib\\site-packages\\IPython\\core\\interactiveshell.py\", line 3343, in run_code\n",
      "    exec(code_obj, self.user_global_ns, self.user_ns)\n",
      "  File \"<ipython-input-6-0d21aaf95e20>\", line 8, in <module>\n",
      "    history = model.fit(np.array(xtrain), np.array(ytrain), nb_epoch=100, batch_size=50,  verbose=1)\n",
      "  File \"C:\\ProgramData\\Anaconda3\\lib\\site-packages\\keras\\engine\\training.py\", line 1239, in fit\n",
      "    validation_freq=validation_freq)\n",
      "  File \"C:\\ProgramData\\Anaconda3\\lib\\site-packages\\keras\\engine\\training_arrays.py\", line 196, in fit_loop\n",
      "    outs = fit_function(ins_batch)\n",
      "  File \"C:\\ProgramData\\Anaconda3\\lib\\site-packages\\tensorflow_core\\python\\keras\\backend.py\", line 3727, in __call__\n",
      "    outputs = self._graph_fn(*converted_inputs)\n",
      "  File \"C:\\ProgramData\\Anaconda3\\lib\\site-packages\\tensorflow_core\\python\\eager\\function.py\", line 1551, in __call__\n",
      "    return self._call_impl(args, kwargs)\n",
      "  File \"C:\\ProgramData\\Anaconda3\\lib\\site-packages\\tensorflow_core\\python\\eager\\function.py\", line 1591, in _call_impl\n",
      "    return self._call_flat(args, self.captured_inputs, cancellation_manager)\n",
      "  File \"C:\\ProgramData\\Anaconda3\\lib\\site-packages\\tensorflow_core\\python\\eager\\function.py\", line 1692, in _call_flat\n",
      "    ctx, args, cancellation_manager=cancellation_manager))\n",
      "  File \"C:\\ProgramData\\Anaconda3\\lib\\site-packages\\tensorflow_core\\python\\eager\\function.py\", line 545, in call\n",
      "    ctx=ctx)\n",
      "  File \"C:\\ProgramData\\Anaconda3\\lib\\site-packages\\tensorflow_core\\python\\eager\\execute.py\", line 67, in quick_execute\n",
      "    six.raise_from(core._status_to_exception(e.code, message), None)\n",
      "  File \"<string>\", line 3, in raise_from\n",
      "tensorflow.python.framework.errors_impl.InternalError:  Blas GEMM launch failed : a.shape=(50, 12), b.shape=(12, 12), m=50, n=12, k=12\n",
      "\t [[node dense_1/MatMul (defined at C:\\ProgramData\\Anaconda3\\lib\\site-packages\\keras\\backend\\tensorflow_backend.py:3009) ]] [Op:__inference_keras_scratch_graph_1062]\n",
      "\n",
      "Function call stack:\n",
      "keras_scratch_graph\n",
      "\n",
      "\n",
      "During handling of the above exception, another exception occurred:\n",
      "\n",
      "Traceback (most recent call last):\n",
      "  File \"C:\\ProgramData\\Anaconda3\\lib\\site-packages\\IPython\\core\\interactiveshell.py\", line 2044, in showtraceback\n",
      "    stb = value._render_traceback_()\n",
      "AttributeError: 'InternalError' object has no attribute '_render_traceback_'\n",
      "\n",
      "During handling of the above exception, another exception occurred:\n",
      "\n",
      "Traceback (most recent call last):\n",
      "  File \"C:\\ProgramData\\Anaconda3\\lib\\site-packages\\IPython\\core\\interactiveshell.py\", line 3263, in run_ast_nodes\n",
      "    if (await self.run_code(code, result,  async_=asy)):\n",
      "  File \"C:\\ProgramData\\Anaconda3\\lib\\site-packages\\IPython\\core\\interactiveshell.py\", line 3360, in run_code\n",
      "    self.showtraceback(running_compiled_code=True)\n",
      "  File \"C:\\ProgramData\\Anaconda3\\lib\\site-packages\\IPython\\core\\interactiveshell.py\", line 2047, in showtraceback\n",
      "    value, tb, tb_offset=tb_offset)\n",
      "  File \"C:\\ProgramData\\Anaconda3\\lib\\site-packages\\IPython\\core\\ultratb.py\", line 1436, in structured_traceback\n",
      "    self, etype, value, tb, tb_offset, number_of_lines_of_context)\n",
      "  File \"C:\\ProgramData\\Anaconda3\\lib\\site-packages\\IPython\\core\\ultratb.py\", line 1336, in structured_traceback\n",
      "    self, etype, value, tb, tb_offset, number_of_lines_of_context\n",
      "  File \"C:\\ProgramData\\Anaconda3\\lib\\site-packages\\IPython\\core\\ultratb.py\", line 1193, in structured_traceback\n",
      "    tb_offset)\n",
      "  File \"C:\\ProgramData\\Anaconda3\\lib\\site-packages\\IPython\\core\\ultratb.py\", line 1150, in format_exception_as_a_whole\n",
      "    last_unique, recursion_repeat = find_recursion(orig_etype, evalue, records)\n",
      "  File \"C:\\ProgramData\\Anaconda3\\lib\\site-packages\\IPython\\core\\ultratb.py\", line 451, in find_recursion\n",
      "    return len(records), 0\n",
      "TypeError: object of type 'NoneType' has no len()\n",
      "\n",
      "During handling of the above exception, another exception occurred:\n",
      "\n",
      "Traceback (most recent call last):\n",
      "  File \"C:\\ProgramData\\Anaconda3\\lib\\site-packages\\IPython\\core\\interactiveshell.py\", line 2044, in showtraceback\n",
      "    stb = value._render_traceback_()\n",
      "AttributeError: 'TypeError' object has no attribute '_render_traceback_'\n",
      "\n",
      "During handling of the above exception, another exception occurred:\n",
      "\n",
      "Traceback (most recent call last):\n",
      "  File \"C:\\ProgramData\\Anaconda3\\lib\\site-packages\\IPython\\core\\ultratb.py\", line 1169, in get_records\n",
      "    return _fixed_getinnerframes(etb, number_of_lines_of_context, tb_offset)\n",
      "  File \"C:\\ProgramData\\Anaconda3\\lib\\site-packages\\IPython\\core\\ultratb.py\", line 316, in wrapped\n",
      "    return f(*args, **kwargs)\n",
      "  File \"C:\\ProgramData\\Anaconda3\\lib\\site-packages\\IPython\\core\\ultratb.py\", line 350, in _fixed_getinnerframes\n",
      "    records = fix_frame_records_filenames(inspect.getinnerframes(etb, context))\n",
      "  File \"C:\\ProgramData\\Anaconda3\\lib\\inspect.py\", line 1502, in getinnerframes\n",
      "    frameinfo = (tb.tb_frame,) + getframeinfo(tb, context)\n",
      "  File \"C:\\ProgramData\\Anaconda3\\lib\\inspect.py\", line 1460, in getframeinfo\n",
      "    filename = getsourcefile(frame) or getfile(frame)\n",
      "  File \"C:\\ProgramData\\Anaconda3\\lib\\inspect.py\", line 696, in getsourcefile\n",
      "    if getattr(getmodule(object, filename), '__loader__', None) is not None:\n",
      "  File \"C:\\ProgramData\\Anaconda3\\lib\\inspect.py\", line 733, in getmodule\n",
      "    if ismodule(module) and hasattr(module, '__file__'):\n",
      "  File \"C:\\ProgramData\\Anaconda3\\lib\\site-packages\\tensorflow\\__init__.py\", line 50, in __getattr__\n",
      "    module = self._load()\n",
      "  File \"C:\\ProgramData\\Anaconda3\\lib\\site-packages\\tensorflow\\__init__.py\", line 44, in _load\n",
      "    module = _importlib.import_module(self.__name__)\n",
      "  File \"C:\\ProgramData\\Anaconda3\\lib\\importlib\\__init__.py\", line 127, in import_module\n",
      "    return _bootstrap._gcd_import(name[level:], package, level)\n",
      "  File \"<frozen importlib._bootstrap>\", line 1006, in _gcd_import\n",
      "  File \"<frozen importlib._bootstrap>\", line 983, in _find_and_load\n",
      "  File \"<frozen importlib._bootstrap>\", line 965, in _find_and_load_unlocked\n",
      "ModuleNotFoundError: No module named 'tensorflow_core.estimator'\n",
      "Traceback (most recent call last):\n",
      "  File \"C:\\ProgramData\\Anaconda3\\lib\\site-packages\\IPython\\core\\interactiveshell.py\", line 3343, in run_code\n",
      "    exec(code_obj, self.user_global_ns, self.user_ns)\n",
      "  File \"<ipython-input-6-0d21aaf95e20>\", line 8, in <module>\n",
      "    history = model.fit(np.array(xtrain), np.array(ytrain), nb_epoch=100, batch_size=50,  verbose=1)\n",
      "  File \"C:\\ProgramData\\Anaconda3\\lib\\site-packages\\keras\\engine\\training.py\", line 1239, in fit\n",
      "    validation_freq=validation_freq)\n",
      "  File \"C:\\ProgramData\\Anaconda3\\lib\\site-packages\\keras\\engine\\training_arrays.py\", line 196, in fit_loop\n",
      "    outs = fit_function(ins_batch)\n",
      "  File \"C:\\ProgramData\\Anaconda3\\lib\\site-packages\\tensorflow_core\\python\\keras\\backend.py\", line 3727, in __call__\n",
      "    outputs = self._graph_fn(*converted_inputs)\n",
      "  File \"C:\\ProgramData\\Anaconda3\\lib\\site-packages\\tensorflow_core\\python\\eager\\function.py\", line 1551, in __call__\n",
      "    return self._call_impl(args, kwargs)\n",
      "  File \"C:\\ProgramData\\Anaconda3\\lib\\site-packages\\tensorflow_core\\python\\eager\\function.py\", line 1591, in _call_impl\n",
      "    return self._call_flat(args, self.captured_inputs, cancellation_manager)\n",
      "  File \"C:\\ProgramData\\Anaconda3\\lib\\site-packages\\tensorflow_core\\python\\eager\\function.py\", line 1692, in _call_flat\n",
      "    ctx, args, cancellation_manager=cancellation_manager))\n",
      "  File \"C:\\ProgramData\\Anaconda3\\lib\\site-packages\\tensorflow_core\\python\\eager\\function.py\", line 545, in call\n",
      "    ctx=ctx)\n",
      "  File \"C:\\ProgramData\\Anaconda3\\lib\\site-packages\\tensorflow_core\\python\\eager\\execute.py\", line 67, in quick_execute\n",
      "    six.raise_from(core._status_to_exception(e.code, message), None)\n",
      "  File \"<string>\", line 3, in raise_from\n",
      "tensorflow.python.framework.errors_impl.InternalError:  Blas GEMM launch failed : a.shape=(50, 12), b.shape=(12, 12), m=50, n=12, k=12\n",
      "\t [[node dense_1/MatMul (defined at C:\\ProgramData\\Anaconda3\\lib\\site-packages\\keras\\backend\\tensorflow_backend.py:3009) ]] [Op:__inference_keras_scratch_graph_1062]\n",
      "\n",
      "Function call stack:\n",
      "keras_scratch_graph\n",
      "\n",
      "\n",
      "During handling of the above exception, another exception occurred:\n",
      "\n",
      "Traceback (most recent call last):\n",
      "  File \"C:\\ProgramData\\Anaconda3\\lib\\site-packages\\IPython\\core\\interactiveshell.py\", line 2044, in showtraceback\n",
      "    stb = value._render_traceback_()\n",
      "AttributeError: 'InternalError' object has no attribute '_render_traceback_'\n",
      "\n",
      "During handling of the above exception, another exception occurred:\n",
      "\n",
      "Traceback (most recent call last):\n",
      "  File \"C:\\ProgramData\\Anaconda3\\lib\\site-packages\\IPython\\core\\interactiveshell.py\", line 3263, in run_ast_nodes\n",
      "    if (await self.run_code(code, result,  async_=asy)):\n",
      "  File \"C:\\ProgramData\\Anaconda3\\lib\\site-packages\\IPython\\core\\interactiveshell.py\", line 3360, in run_code\n",
      "    self.showtraceback(running_compiled_code=True)\n",
      "  File \"C:\\ProgramData\\Anaconda3\\lib\\site-packages\\IPython\\core\\interactiveshell.py\", line 2047, in showtraceback\n",
      "    value, tb, tb_offset=tb_offset)\n",
      "  File \"C:\\ProgramData\\Anaconda3\\lib\\site-packages\\IPython\\core\\ultratb.py\", line 1436, in structured_traceback\n",
      "    self, etype, value, tb, tb_offset, number_of_lines_of_context)\n",
      "  File \"C:\\ProgramData\\Anaconda3\\lib\\site-packages\\IPython\\core\\ultratb.py\", line 1336, in structured_traceback\n",
      "    self, etype, value, tb, tb_offset, number_of_lines_of_context\n",
      "  File \"C:\\ProgramData\\Anaconda3\\lib\\site-packages\\IPython\\core\\ultratb.py\", line 1193, in structured_traceback\n",
      "    tb_offset)\n",
      "  File \"C:\\ProgramData\\Anaconda3\\lib\\site-packages\\IPython\\core\\ultratb.py\", line 1150, in format_exception_as_a_whole\n",
      "    last_unique, recursion_repeat = find_recursion(orig_etype, evalue, records)\n",
      "  File \"C:\\ProgramData\\Anaconda3\\lib\\site-packages\\IPython\\core\\ultratb.py\", line 451, in find_recursion\n",
      "    return len(records), 0\n",
      "TypeError: object of type 'NoneType' has no len()\n",
      "\n",
      "During handling of the above exception, another exception occurred:\n",
      "\n",
      "Traceback (most recent call last):\n",
      "  File \"C:\\ProgramData\\Anaconda3\\lib\\site-packages\\IPython\\core\\interactiveshell.py\", line 2044, in showtraceback\n",
      "    stb = value._render_traceback_()\n",
      "AttributeError: 'TypeError' object has no attribute '_render_traceback_'\n",
      "\n",
      "During handling of the above exception, another exception occurred:\n",
      "\n",
      "Traceback (most recent call last):\n",
      "  File \"C:\\ProgramData\\Anaconda3\\lib\\site-packages\\IPython\\core\\interactiveshell.py\", line 2895, in _run_cell\n",
      "    return runner(coro)\n",
      "  File \"C:\\ProgramData\\Anaconda3\\lib\\site-packages\\IPython\\core\\async_helpers.py\", line 68, in _pseudo_sync_runner\n",
      "    coro.send(None)\n",
      "  File \"C:\\ProgramData\\Anaconda3\\lib\\site-packages\\IPython\\core\\interactiveshell.py\", line 3072, in run_cell_async\n",
      "    interactivity=interactivity, compiler=compiler, result=result)\n",
      "  File \"C:\\ProgramData\\Anaconda3\\lib\\site-packages\\IPython\\core\\interactiveshell.py\", line 3282, in run_ast_nodes\n",
      "    self.showtraceback()\n",
      "  File \"C:\\ProgramData\\Anaconda3\\lib\\site-packages\\IPython\\core\\interactiveshell.py\", line 2047, in showtraceback\n",
      "    value, tb, tb_offset=tb_offset)\n",
      "  File \"C:\\ProgramData\\Anaconda3\\lib\\site-packages\\IPython\\core\\ultratb.py\", line 1436, in structured_traceback\n",
      "    self, etype, value, tb, tb_offset, number_of_lines_of_context)\n",
      "  File \"C:\\ProgramData\\Anaconda3\\lib\\site-packages\\IPython\\core\\ultratb.py\", line 1336, in structured_traceback\n",
      "    self, etype, value, tb, tb_offset, number_of_lines_of_context\n",
      "  File \"C:\\ProgramData\\Anaconda3\\lib\\site-packages\\IPython\\core\\ultratb.py\", line 1211, in structured_traceback\n",
      "    chained_exceptions_tb_offset)\n",
      "  File \"C:\\ProgramData\\Anaconda3\\lib\\site-packages\\IPython\\core\\ultratb.py\", line 1150, in format_exception_as_a_whole\n",
      "    last_unique, recursion_repeat = find_recursion(orig_etype, evalue, records)\n",
      "  File \"C:\\ProgramData\\Anaconda3\\lib\\site-packages\\IPython\\core\\ultratb.py\", line 451, in find_recursion\n",
      "    return len(records), 0\n",
      "TypeError: object of type 'NoneType' has no len()\n",
      "\n",
      "During handling of the above exception, another exception occurred:\n",
      "\n",
      "Traceback (most recent call last):\n",
      "  File \"C:\\ProgramData\\Anaconda3\\lib\\site-packages\\IPython\\core\\interactiveshell.py\", line 2044, in showtraceback\n",
      "    stb = value._render_traceback_()\n",
      "AttributeError: 'TypeError' object has no attribute '_render_traceback_'\n",
      "\n",
      "During handling of the above exception, another exception occurred:\n",
      "\n",
      "Traceback (most recent call last):\n",
      "  File \"C:\\ProgramData\\Anaconda3\\lib\\site-packages\\IPython\\core\\ultratb.py\", line 1169, in get_records\n",
      "    return _fixed_getinnerframes(etb, number_of_lines_of_context, tb_offset)\n",
      "  File \"C:\\ProgramData\\Anaconda3\\lib\\site-packages\\IPython\\core\\ultratb.py\", line 316, in wrapped\n",
      "    return f(*args, **kwargs)\n",
      "  File \"C:\\ProgramData\\Anaconda3\\lib\\site-packages\\IPython\\core\\ultratb.py\", line 350, in _fixed_getinnerframes\n",
      "    records = fix_frame_records_filenames(inspect.getinnerframes(etb, context))\n",
      "  File \"C:\\ProgramData\\Anaconda3\\lib\\inspect.py\", line 1502, in getinnerframes\n",
      "    frameinfo = (tb.tb_frame,) + getframeinfo(tb, context)\n",
      "  File \"C:\\ProgramData\\Anaconda3\\lib\\inspect.py\", line 1460, in getframeinfo\n",
      "    filename = getsourcefile(frame) or getfile(frame)\n",
      "  File \"C:\\ProgramData\\Anaconda3\\lib\\inspect.py\", line 696, in getsourcefile\n",
      "    if getattr(getmodule(object, filename), '__loader__', None) is not None:\n",
      "  File \"C:\\ProgramData\\Anaconda3\\lib\\inspect.py\", line 733, in getmodule\n",
      "    if ismodule(module) and hasattr(module, '__file__'):\n",
      "  File \"C:\\ProgramData\\Anaconda3\\lib\\site-packages\\tensorflow\\__init__.py\", line 50, in __getattr__\n",
      "    module = self._load()\n",
      "  File \"C:\\ProgramData\\Anaconda3\\lib\\site-packages\\tensorflow\\__init__.py\", line 44, in _load\n",
      "    module = _importlib.import_module(self.__name__)\n",
      "  File \"C:\\ProgramData\\Anaconda3\\lib\\importlib\\__init__.py\", line 127, in import_module\n",
      "    return _bootstrap._gcd_import(name[level:], package, level)\n",
      "  File \"<frozen importlib._bootstrap>\", line 1006, in _gcd_import\n",
      "  File \"<frozen importlib._bootstrap>\", line 983, in _find_and_load\n",
      "  File \"<frozen importlib._bootstrap>\", line 965, in _find_and_load_unlocked\n",
      "ModuleNotFoundError: No module named 'tensorflow_core.estimator'\n"
     ]
    }
   ],
   "source": [
    "# Using Relu activation, and Adam optimizer, 50 epochs\n",
    "model = Sequential()\n",
    "model.add(Dense(12, input_dim=12, init='uniform', activation='relu'))\n",
    "model.add(Dense(10, init='uniform', activation='relu'))\n",
    "model.add(Dense(1, init='uniform', activation='relu'))\n",
    "model.compile(loss='binary_crossentropy', optimizer='adam', metrics=['accuracy'])\n",
    "# Train model\n",
    "history = model.fit(np.array(xtrain), np.array(ytrain), nb_epoch=100, batch_size=50,  verbose=1)\n",
    "# Print Accuracy\n",
    "scores = model.evaluate(np.array(xtest), np.array(ytest) )\n",
    "print(\"%s: %.2f%%\" % (model.metrics_names[1], scores[1]*100))"
   ]
  },
  {
   "cell_type": "code",
   "execution_count": null,
   "metadata": {},
   "outputs": [
    {
     "name": "stderr",
     "output_type": "stream",
     "text": [
      "ERROR:root:Internal Python error in the inspect module.\n",
      "Below is the traceback from this internal error.\n",
      "\n",
      "ERROR:root:Internal Python error in the inspect module.\n",
      "Below is the traceback from this internal error.\n",
      "\n",
      "ERROR:root:Internal Python error in the inspect module.\n",
      "Below is the traceback from this internal error.\n",
      "\n"
     ]
    },
    {
     "name": "stdout",
     "output_type": "stream",
     "text": [
      "Traceback (most recent call last):\n",
      "  File \"C:\\ProgramData\\Anaconda3\\lib\\site-packages\\IPython\\core\\interactiveshell.py\", line 3343, in run_code\n",
      "    exec(code_obj, self.user_global_ns, self.user_ns)\n",
      "  File \"<ipython-input-6-d31fe7f069c0>\", line 4, in <module>\n",
      "    y_pred = classifier.predict(xtest)\n",
      "NameError: name 'classifier' is not defined\n",
      "\n",
      "During handling of the above exception, another exception occurred:\n",
      "\n",
      "Traceback (most recent call last):\n",
      "  File \"C:\\ProgramData\\Anaconda3\\lib\\site-packages\\IPython\\core\\interactiveshell.py\", line 2044, in showtraceback\n",
      "    stb = value._render_traceback_()\n",
      "AttributeError: 'NameError' object has no attribute '_render_traceback_'\n",
      "\n",
      "During handling of the above exception, another exception occurred:\n",
      "\n",
      "Traceback (most recent call last):\n",
      "  File \"C:\\ProgramData\\Anaconda3\\lib\\site-packages\\IPython\\core\\ultratb.py\", line 1169, in get_records\n",
      "    return _fixed_getinnerframes(etb, number_of_lines_of_context, tb_offset)\n",
      "  File \"C:\\ProgramData\\Anaconda3\\lib\\site-packages\\IPython\\core\\ultratb.py\", line 316, in wrapped\n",
      "    return f(*args, **kwargs)\n",
      "  File \"C:\\ProgramData\\Anaconda3\\lib\\site-packages\\IPython\\core\\ultratb.py\", line 350, in _fixed_getinnerframes\n",
      "    records = fix_frame_records_filenames(inspect.getinnerframes(etb, context))\n",
      "  File \"C:\\ProgramData\\Anaconda3\\lib\\inspect.py\", line 1502, in getinnerframes\n",
      "    frameinfo = (tb.tb_frame,) + getframeinfo(tb, context)\n",
      "  File \"C:\\ProgramData\\Anaconda3\\lib\\inspect.py\", line 1460, in getframeinfo\n",
      "    filename = getsourcefile(frame) or getfile(frame)\n",
      "  File \"C:\\ProgramData\\Anaconda3\\lib\\inspect.py\", line 696, in getsourcefile\n",
      "    if getattr(getmodule(object, filename), '__loader__', None) is not None:\n",
      "  File \"C:\\ProgramData\\Anaconda3\\lib\\inspect.py\", line 733, in getmodule\n",
      "    if ismodule(module) and hasattr(module, '__file__'):\n",
      "  File \"C:\\ProgramData\\Anaconda3\\lib\\site-packages\\tensorflow\\__init__.py\", line 50, in __getattr__\n",
      "    module = self._load()\n",
      "  File \"C:\\ProgramData\\Anaconda3\\lib\\site-packages\\tensorflow\\__init__.py\", line 44, in _load\n",
      "    module = _importlib.import_module(self.__name__)\n",
      "  File \"C:\\ProgramData\\Anaconda3\\lib\\importlib\\__init__.py\", line 127, in import_module\n",
      "    return _bootstrap._gcd_import(name[level:], package, level)\n",
      "  File \"<frozen importlib._bootstrap>\", line 1006, in _gcd_import\n",
      "  File \"<frozen importlib._bootstrap>\", line 983, in _find_and_load\n",
      "  File \"<frozen importlib._bootstrap>\", line 965, in _find_and_load_unlocked\n",
      "ModuleNotFoundError: No module named 'tensorflow_core.estimator'\n",
      "ERROR! Session/line number was not unique in database. History logging moved to new session 7163\n",
      "Traceback (most recent call last):\n",
      "  File \"C:\\ProgramData\\Anaconda3\\lib\\site-packages\\IPython\\core\\interactiveshell.py\", line 3343, in run_code\n",
      "    exec(code_obj, self.user_global_ns, self.user_ns)\n",
      "  File \"<ipython-input-6-d31fe7f069c0>\", line 4, in <module>\n",
      "    y_pred = classifier.predict(xtest)\n",
      "NameError: name 'classifier' is not defined\n",
      "\n",
      "During handling of the above exception, another exception occurred:\n",
      "\n",
      "Traceback (most recent call last):\n",
      "  File \"C:\\ProgramData\\Anaconda3\\lib\\site-packages\\IPython\\core\\interactiveshell.py\", line 2044, in showtraceback\n",
      "    stb = value._render_traceback_()\n",
      "AttributeError: 'NameError' object has no attribute '_render_traceback_'\n",
      "\n",
      "During handling of the above exception, another exception occurred:\n",
      "\n",
      "Traceback (most recent call last):\n",
      "  File \"C:\\ProgramData\\Anaconda3\\lib\\site-packages\\IPython\\core\\interactiveshell.py\", line 3263, in run_ast_nodes\n",
      "    if (await self.run_code(code, result,  async_=asy)):\n",
      "  File \"C:\\ProgramData\\Anaconda3\\lib\\site-packages\\IPython\\core\\interactiveshell.py\", line 3360, in run_code\n",
      "    self.showtraceback(running_compiled_code=True)\n",
      "  File \"C:\\ProgramData\\Anaconda3\\lib\\site-packages\\IPython\\core\\interactiveshell.py\", line 2047, in showtraceback\n",
      "    value, tb, tb_offset=tb_offset)\n",
      "  File \"C:\\ProgramData\\Anaconda3\\lib\\site-packages\\IPython\\core\\ultratb.py\", line 1436, in structured_traceback\n",
      "    self, etype, value, tb, tb_offset, number_of_lines_of_context)\n",
      "  File \"C:\\ProgramData\\Anaconda3\\lib\\site-packages\\IPython\\core\\ultratb.py\", line 1336, in structured_traceback\n",
      "    self, etype, value, tb, tb_offset, number_of_lines_of_context\n",
      "  File \"C:\\ProgramData\\Anaconda3\\lib\\site-packages\\IPython\\core\\ultratb.py\", line 1193, in structured_traceback\n",
      "    tb_offset)\n",
      "  File \"C:\\ProgramData\\Anaconda3\\lib\\site-packages\\IPython\\core\\ultratb.py\", line 1150, in format_exception_as_a_whole\n",
      "    last_unique, recursion_repeat = find_recursion(orig_etype, evalue, records)\n",
      "  File \"C:\\ProgramData\\Anaconda3\\lib\\site-packages\\IPython\\core\\ultratb.py\", line 451, in find_recursion\n",
      "    return len(records), 0\n",
      "TypeError: object of type 'NoneType' has no len()\n",
      "\n",
      "During handling of the above exception, another exception occurred:\n",
      "\n",
      "Traceback (most recent call last):\n",
      "  File \"C:\\ProgramData\\Anaconda3\\lib\\site-packages\\IPython\\core\\interactiveshell.py\", line 2044, in showtraceback\n",
      "    stb = value._render_traceback_()\n",
      "AttributeError: 'TypeError' object has no attribute '_render_traceback_'\n",
      "\n",
      "During handling of the above exception, another exception occurred:\n",
      "\n",
      "Traceback (most recent call last):\n",
      "  File \"C:\\ProgramData\\Anaconda3\\lib\\site-packages\\IPython\\core\\ultratb.py\", line 1169, in get_records\n",
      "    return _fixed_getinnerframes(etb, number_of_lines_of_context, tb_offset)\n",
      "  File \"C:\\ProgramData\\Anaconda3\\lib\\site-packages\\IPython\\core\\ultratb.py\", line 316, in wrapped\n",
      "    return f(*args, **kwargs)\n",
      "  File \"C:\\ProgramData\\Anaconda3\\lib\\site-packages\\IPython\\core\\ultratb.py\", line 350, in _fixed_getinnerframes\n",
      "    records = fix_frame_records_filenames(inspect.getinnerframes(etb, context))\n",
      "  File \"C:\\ProgramData\\Anaconda3\\lib\\inspect.py\", line 1502, in getinnerframes\n",
      "    frameinfo = (tb.tb_frame,) + getframeinfo(tb, context)\n",
      "  File \"C:\\ProgramData\\Anaconda3\\lib\\inspect.py\", line 1460, in getframeinfo\n",
      "    filename = getsourcefile(frame) or getfile(frame)\n",
      "  File \"C:\\ProgramData\\Anaconda3\\lib\\inspect.py\", line 696, in getsourcefile\n",
      "    if getattr(getmodule(object, filename), '__loader__', None) is not None:\n",
      "  File \"C:\\ProgramData\\Anaconda3\\lib\\inspect.py\", line 733, in getmodule\n",
      "    if ismodule(module) and hasattr(module, '__file__'):\n",
      "  File \"C:\\ProgramData\\Anaconda3\\lib\\site-packages\\tensorflow\\__init__.py\", line 50, in __getattr__\n",
      "    module = self._load()\n",
      "  File \"C:\\ProgramData\\Anaconda3\\lib\\site-packages\\tensorflow\\__init__.py\", line 44, in _load\n",
      "    module = _importlib.import_module(self.__name__)\n",
      "  File \"C:\\ProgramData\\Anaconda3\\lib\\importlib\\__init__.py\", line 127, in import_module\n",
      "    return _bootstrap._gcd_import(name[level:], package, level)\n",
      "  File \"<frozen importlib._bootstrap>\", line 1006, in _gcd_import\n",
      "  File \"<frozen importlib._bootstrap>\", line 983, in _find_and_load\n",
      "  File \"<frozen importlib._bootstrap>\", line 965, in _find_and_load_unlocked\n",
      "ModuleNotFoundError: No module named 'tensorflow_core.estimator'\n",
      "Traceback (most recent call last):\n",
      "  File \"C:\\ProgramData\\Anaconda3\\lib\\site-packages\\IPython\\core\\interactiveshell.py\", line 3343, in run_code\n",
      "    exec(code_obj, self.user_global_ns, self.user_ns)\n",
      "  File \"<ipython-input-6-d31fe7f069c0>\", line 4, in <module>\n",
      "    y_pred = classifier.predict(xtest)\n",
      "NameError: name 'classifier' is not defined\n",
      "\n",
      "During handling of the above exception, another exception occurred:\n",
      "\n",
      "Traceback (most recent call last):\n",
      "  File \"C:\\ProgramData\\Anaconda3\\lib\\site-packages\\IPython\\core\\interactiveshell.py\", line 2044, in showtraceback\n",
      "    stb = value._render_traceback_()\n",
      "AttributeError: 'NameError' object has no attribute '_render_traceback_'\n",
      "\n",
      "During handling of the above exception, another exception occurred:\n",
      "\n",
      "Traceback (most recent call last):\n",
      "  File \"C:\\ProgramData\\Anaconda3\\lib\\site-packages\\IPython\\core\\interactiveshell.py\", line 3263, in run_ast_nodes\n",
      "    if (await self.run_code(code, result,  async_=asy)):\n",
      "  File \"C:\\ProgramData\\Anaconda3\\lib\\site-packages\\IPython\\core\\interactiveshell.py\", line 3360, in run_code\n",
      "    self.showtraceback(running_compiled_code=True)\n",
      "  File \"C:\\ProgramData\\Anaconda3\\lib\\site-packages\\IPython\\core\\interactiveshell.py\", line 2047, in showtraceback\n",
      "    value, tb, tb_offset=tb_offset)\n",
      "  File \"C:\\ProgramData\\Anaconda3\\lib\\site-packages\\IPython\\core\\ultratb.py\", line 1436, in structured_traceback\n",
      "    self, etype, value, tb, tb_offset, number_of_lines_of_context)\n",
      "  File \"C:\\ProgramData\\Anaconda3\\lib\\site-packages\\IPython\\core\\ultratb.py\", line 1336, in structured_traceback\n",
      "    self, etype, value, tb, tb_offset, number_of_lines_of_context\n",
      "  File \"C:\\ProgramData\\Anaconda3\\lib\\site-packages\\IPython\\core\\ultratb.py\", line 1193, in structured_traceback\n",
      "    tb_offset)\n",
      "  File \"C:\\ProgramData\\Anaconda3\\lib\\site-packages\\IPython\\core\\ultratb.py\", line 1150, in format_exception_as_a_whole\n",
      "    last_unique, recursion_repeat = find_recursion(orig_etype, evalue, records)\n",
      "  File \"C:\\ProgramData\\Anaconda3\\lib\\site-packages\\IPython\\core\\ultratb.py\", line 451, in find_recursion\n",
      "    return len(records), 0\n",
      "TypeError: object of type 'NoneType' has no len()\n",
      "\n",
      "During handling of the above exception, another exception occurred:\n",
      "\n",
      "Traceback (most recent call last):\n",
      "  File \"C:\\ProgramData\\Anaconda3\\lib\\site-packages\\IPython\\core\\interactiveshell.py\", line 2044, in showtraceback\n",
      "    stb = value._render_traceback_()\n",
      "AttributeError: 'TypeError' object has no attribute '_render_traceback_'\n",
      "\n",
      "During handling of the above exception, another exception occurred:\n",
      "\n",
      "Traceback (most recent call last):\n",
      "  File \"C:\\ProgramData\\Anaconda3\\lib\\site-packages\\IPython\\core\\interactiveshell.py\", line 2895, in _run_cell\n",
      "    return runner(coro)\n",
      "  File \"C:\\ProgramData\\Anaconda3\\lib\\site-packages\\IPython\\core\\async_helpers.py\", line 68, in _pseudo_sync_runner\n",
      "    coro.send(None)\n",
      "  File \"C:\\ProgramData\\Anaconda3\\lib\\site-packages\\IPython\\core\\interactiveshell.py\", line 3072, in run_cell_async\n",
      "    interactivity=interactivity, compiler=compiler, result=result)\n",
      "  File \"C:\\ProgramData\\Anaconda3\\lib\\site-packages\\IPython\\core\\interactiveshell.py\", line 3282, in run_ast_nodes\n",
      "    self.showtraceback()\n",
      "  File \"C:\\ProgramData\\Anaconda3\\lib\\site-packages\\IPython\\core\\interactiveshell.py\", line 2047, in showtraceback\n",
      "    value, tb, tb_offset=tb_offset)\n",
      "  File \"C:\\ProgramData\\Anaconda3\\lib\\site-packages\\IPython\\core\\ultratb.py\", line 1436, in structured_traceback\n",
      "    self, etype, value, tb, tb_offset, number_of_lines_of_context)\n",
      "  File \"C:\\ProgramData\\Anaconda3\\lib\\site-packages\\IPython\\core\\ultratb.py\", line 1336, in structured_traceback\n",
      "    self, etype, value, tb, tb_offset, number_of_lines_of_context\n",
      "  File \"C:\\ProgramData\\Anaconda3\\lib\\site-packages\\IPython\\core\\ultratb.py\", line 1211, in structured_traceback\n",
      "    chained_exceptions_tb_offset)\n",
      "  File \"C:\\ProgramData\\Anaconda3\\lib\\site-packages\\IPython\\core\\ultratb.py\", line 1150, in format_exception_as_a_whole\n",
      "    last_unique, recursion_repeat = find_recursion(orig_etype, evalue, records)\n",
      "  File \"C:\\ProgramData\\Anaconda3\\lib\\site-packages\\IPython\\core\\ultratb.py\", line 451, in find_recursion\n",
      "    return len(records), 0\n",
      "TypeError: object of type 'NoneType' has no len()\n",
      "\n",
      "During handling of the above exception, another exception occurred:\n",
      "\n",
      "Traceback (most recent call last):\n",
      "  File \"C:\\ProgramData\\Anaconda3\\lib\\site-packages\\IPython\\core\\interactiveshell.py\", line 2044, in showtraceback\n",
      "    stb = value._render_traceback_()\n",
      "AttributeError: 'TypeError' object has no attribute '_render_traceback_'\n",
      "\n",
      "During handling of the above exception, another exception occurred:\n",
      "\n",
      "Traceback (most recent call last):\n",
      "  File \"C:\\ProgramData\\Anaconda3\\lib\\site-packages\\IPython\\core\\ultratb.py\", line 1169, in get_records\n",
      "    return _fixed_getinnerframes(etb, number_of_lines_of_context, tb_offset)\n",
      "  File \"C:\\ProgramData\\Anaconda3\\lib\\site-packages\\IPython\\core\\ultratb.py\", line 316, in wrapped\n",
      "    return f(*args, **kwargs)\n",
      "  File \"C:\\ProgramData\\Anaconda3\\lib\\site-packages\\IPython\\core\\ultratb.py\", line 350, in _fixed_getinnerframes\n",
      "    records = fix_frame_records_filenames(inspect.getinnerframes(etb, context))\n",
      "  File \"C:\\ProgramData\\Anaconda3\\lib\\inspect.py\", line 1502, in getinnerframes\n",
      "    frameinfo = (tb.tb_frame,) + getframeinfo(tb, context)\n",
      "  File \"C:\\ProgramData\\Anaconda3\\lib\\inspect.py\", line 1460, in getframeinfo\n",
      "    filename = getsourcefile(frame) or getfile(frame)\n",
      "  File \"C:\\ProgramData\\Anaconda3\\lib\\inspect.py\", line 696, in getsourcefile\n",
      "    if getattr(getmodule(object, filename), '__loader__', None) is not None:\n",
      "  File \"C:\\ProgramData\\Anaconda3\\lib\\inspect.py\", line 733, in getmodule\n",
      "    if ismodule(module) and hasattr(module, '__file__'):\n",
      "  File \"C:\\ProgramData\\Anaconda3\\lib\\site-packages\\tensorflow\\__init__.py\", line 50, in __getattr__\n",
      "    module = self._load()\n",
      "  File \"C:\\ProgramData\\Anaconda3\\lib\\site-packages\\tensorflow\\__init__.py\", line 44, in _load\n",
      "    module = _importlib.import_module(self.__name__)\n",
      "  File \"C:\\ProgramData\\Anaconda3\\lib\\importlib\\__init__.py\", line 127, in import_module\n",
      "    return _bootstrap._gcd_import(name[level:], package, level)\n",
      "  File \"<frozen importlib._bootstrap>\", line 1006, in _gcd_import\n",
      "  File \"<frozen importlib._bootstrap>\", line 983, in _find_and_load\n",
      "  File \"<frozen importlib._bootstrap>\", line 965, in _find_and_load_unlocked\n",
      "ModuleNotFoundError: No module named 'tensorflow_core.estimator'\n"
     ]
    }
   ],
   "source": [
    "\n",
    "# Part 3 - Making predictions and evaluating the model\n",
    "\n",
    "# Predicting the Test set results\n",
    "y_pred = classifier.predict(xtest)\n",
    "y_pred = (y_pred > 0.5)\n",
    "\n",
    "# Making the Confusion Matrix\n",
    "from sklearn.metrics import confusion_matrix\n",
    "cm = confusion_matrix(ytest, y_pred)\n",
    "\n",
    "\n",
    "print(history.history.keys())\n"
   ]
  }
 ],
 "metadata": {
  "kernelspec": {
   "display_name": "Python 3",
   "language": "python",
   "name": "python3"
  },
  "language_info": {
   "codemirror_mode": {
    "name": "ipython",
    "version": 3
   },
   "file_extension": ".py",
   "mimetype": "text/x-python",
   "name": "python",
   "nbconvert_exporter": "python",
   "pygments_lexer": "ipython3",
   "version": "3.7.7"
  }
 },
 "nbformat": 4,
 "nbformat_minor": 4
}
